Workbook

Sheet Данные
J1: Лекции | K1: Практ. | L1: Лаб.р. | M1: конс. | N1: экз | O1: диф.зач | P1: зач | Q1: курсов.р | R1: ГЭК (защита) | S1: ГЭК (экзамен) | T1: Контроль | U1: Практики | V1: Рук-во | AC1: учебный год | AD1: 2015/2016 | AH1: 2016/2017 | AL1: 2017/2018 | AP1: 2018/2019 | AT1: 2019/2020 | AX1: 2020/2021 | BB1: 2021/2022 | BG1: Стандарт часов по должностям
A2: Код УП | B2: Год нагрузки | C2: Кафедра | D2: ФИО | E2: Степень | F2: Должность | G2: Ставка | H2: Код РУП | I2: Дисциплина / практика / ВКР / ГИА | J2: Часы | W2: Студ. | X2: Количество групп | Y2: Количество подгрупп | Z2: Специальность | AA2: Вид нагрузки | AC2: курс | AD2: 1 | AE2: 2 | AF2: 3 | AG2: 4 | AH2: 1 | AI2: 2 | AJ2: 3 | AK2: 4 | AL2: 1 | AM2: 2 | AN2: 3 | AO2: 4 | AP2: 1 | AQ2: 2 | AR2: 3 | AS2: 4 | AT2: 1 | AU2: 2 | AV2: 3 | AW2: 4 | AX2: 1 | AY2: 2 | AZ2: 3 | BA2: 4 | BB2: 1 | BC2: 2 | BD2: 3 | BE2: 4 | BG2: Должность | BH2: Часы
A3: 3250 | B3: 2015 | C3: компьютерных технологий и электронного обучения | D3: Гончарова Светлана Викторовна | E3: кандидат педагогических наук | F3: доцент | G3: 1 | H3: 13809 | I3: Информатика | J3: 34 | L3: 102 | T3: 12 | W3: =IFERROR(OFFSET($AC$11,0,MATCH(H3,$AD$4:$BE$4,0)),IFERROR(OFFSET($AC$12,0,MATCH(H3,$AD$5:$BE$5,0)),MOD(H3,20)+7)) -> 16 | X3: =IF(W3<=30, "1", "2") -> 1 | Y3: =IF(W3<=15, "1", IF(W3<=30, "2", IF(W3<=45, "3", IF(W3<=60, "4")))) -> 2 | AA3: осн | AC3: год поступления | AD3: 2015 | AE3: 2014 | AF3: 2013 | AG3: 2012 | AH3: 2016 | AI3: 2015 | AJ3: 2014 | AK3: 2013 | AL3: 2017 | AM3: 2016 | AN3: 2015 | AO3: 2014 | AP3: 2018 | AQ3: 2017 | AR3: 2016 | AS3: 2015 | AT3: 2019 | AU3: 2018 | AV3: 2017 | AW3: 2016 | AX3: 2020 | AY3: 2019 | AZ3: 2018 | BA3: 2017 | BB3: 2021 | BC3: 2020 | BD3: 2019 | BE3: 2018 | BG3: заведующий кафедрой | BH3: 700
A4: 4276 | B4: 2015 | C4: компьютерных технологий и электронного обучения | D4: Абрамян Геннадий Владимирович | E4: доктор педагогических наук | F4: профессор | G4: 1 | H4: 13818 | I4: Информационное обеспечение технологического образования. Применение Интернет-технологий в технологическом образовании | J4: 18 | L4: 54 | T4: 21 | W4: =IFERROR(OFFSET($AC$11,0,MATCH(H4,$AD$4:$BE$4,0)),IFERROR(OFFSET($AC$12,0,MATCH(H4,$AD$5:$BE$5,0)),MOD(H4,20)+7)) -> 25 | X4: =IF(W4<=30, "1", "2") -> 1 | Y4: =IF(W4<=15, "1", IF(W4<=30, "2", IF(W4<=45, "3", IF(W4<=60, "4")))) -> 2 | AA4: осн | AC4: Бакалавры (ИВТ) | AD4: 14014 | AE4: 24098 | AF4: 11090 | AG4: 12090 | AH4: 15177 | AI4: 15377 | AJ4: 25432 | AK4: 23456 | AL4: 16591 | AM4: 16002 | AN4: 16003 | AO4: 16457 | AP4: 17043 | AQ4: 17236 | AR4: 17232 | AS4: 17231 | AT4: 19321 | AU4: 2 курс (б) 2018 год/пост | AV4: 3 курс 2017 год/пост | AW4: 4 курс 2016 год/пост | AX4: 10980 | AY4: 19000 | AZ4: 3 курс 2018 год/пост | BA4: 4 курс 2017 год/пост | BB4: 19001 | BC4: 23000 | BD4: 25000 | BE4: 4 курс 2018 год/пост | BG4: профессор | BH4: 750
A5: 4276 | B5: 2015 | C5: компьютерных технологий и электронного обучения | D5: Авксентьева Елена Юрьевна | E5: кандидат педагогических наук | F5: доцент | G5: 1 | H5: 13818 | I5: Информационные технологии | T5: 15 | W5: =IFERROR(OFFSET($AC$11,0,MATCH(H5,$AD$4:$BE$4,0)),IFERROR(OFFSET($AC$12,0,MATCH(H5,$AD$5:$BE$5,0)),MOD(H5,20)+7)) -> 25 | X5: =IF(W5<=30, "1", "2") -> 1 | Y5: =IF(W5<=15, "1", IF(W5<=30, "2", IF(W5<=45, "3", IF(W5<=60, "4")))) -> 2 | AA5: осн | AC5: Магистры (КЭО) | AD5: 14020 | AE5: 34567 | AH5: 34789 | AI5: 12987 | AL5: 16595 | AM5: 15764 | AP5: 17048 | AQ5: 17248 | AT5: 18945 | AU5: 2 курс (м) 2018 год/пост | AX5: 23900 | AY5: 15999 | BB5: 12000 | BC5: 24000 | BG5: доцент | BH5: 800
A6: 4276 | B6: 2015 | C6: компьютерных технологий и электронного обучения | D6: Гончарова Светлана Викторовна | E6: кандидат педагогических наук | F6: доцент | G6: 1 | H6: 13818 | I6: Информационные технологии | J6: 9 | K6: 32 | T6: 3 | W6: =IFERROR(OFFSET($AC$11,0,MATCH(H6,$AD$4:$BE$4,0)),IFERROR(OFFSET($AC$12,0,MATCH(H6,$AD$5:$BE$5,0)),MOD(H6,20)+7)) -> 25 | X6: =IF(W6<=30, "1", "2") -> 1 | Y6: =IF(W6<=15, "1", IF(W6<=30, "2", IF(W6<=45, "3", IF(W6<=60, "4")))) -> 2 | AA6: осн | BG6: старший преподаватель | BH6: 850
A7: 4276 | B7: 2015 | C7: компьютерных технологий и электронного обучения | D7: Ильина Татьяна Сергеевна | E7: нет | F7: старший преподаватель | G7: 1 | H7: 13818 | I7: Информационные технологии | K7: 64 | T7: 3 | W7: =IFERROR(OFFSET($AC$11,0,MATCH(H7,$AD$4:$BE$4,0)),IFERROR(OFFSET($AC$12,0,MATCH(H7,$AD$5:$BE$5,0)),MOD(H7,20)+7)) -> 25 | X7: =IF(W7<=30, "1", "2") -> 1 | Y7: =IF(W7<=15, "1", IF(W7<=30, "2", IF(W7<=45, "3", IF(W7<=60, "4")))) -> 2 | AA7: осн | BG7: ассистент | BH7: 900
A8: 4276 | B8: 2016 | C8: компьютерных технологий и электронного обучения | D8: Готская Ирина Борисовна | E8: доктор педагогических наук | F8: профессор | G8: 1 | H8: 14784 | I8: Информационное обеспечение технологического образования. Применение электронных образовательных ресурсов в технологическом образовании | J8: 32 | L8: 120 | T8: 21 | W8: =IFERROR(OFFSET($AC$11,0,MATCH(H8,$AD$4:$BE$4,0)),IFERROR(OFFSET($AC$12,0,MATCH(H8,$AD$5:$BE$5,0)),MOD(H8,20)+7)) -> 11 | X8: =IF(W8<=30, "1", "2") -> 1 | Y8: =IF(W8<=15, "1", IF(W8<=30, "2", IF(W8<=45, "3", IF(W8<=60, "4")))) -> 1 | AA8: осн | AC8: учебный год | AD8: 2015/2016 | AH8: 2016/2017 | AL8: 2017/2018 | AP8: 2018/2019 | AT8: 2019/2020 | AX8: 2020/2021 | BB8: 2021/2022 | BG8: эксперт-программист | BH8: 900
A9: 4276 | B9: 2017 | C9: компьютерных технологий и электронного обучения | D9: Готская Ирина Борисовна | E9: доктор педагогических наук | F9: профессор | G9: 1 | H9: 16006 | I9: Информационное обеспечение технологического образования. Информационное обеспечение инновационной технологической деятельности | J9: 16 | L9: 60 | T9: 11 | W9: =IFERROR(OFFSET($AC$11,0,MATCH(H9,$AD$4:$BE$4,0)),IFERROR(OFFSET($AC$12,0,MATCH(H9,$AD$5:$BE$5,0)),MOD(H9,20)+7)) -> 13 | X9: =IF(W9<=30, "1", "2") -> 1 | Y9: =IF(W9<=15, "1", IF(W9<=30, "2", IF(W9<=45, "3", IF(W9<=60, "4")))) -> 1 | AA9: осн | AC9: курс | AD9: 1 | AE9: 2 | AF9: 3 | AG9: 4 | AH9: 1 | AI9: 2 | AJ9: 3 | AK9: 4 | AL9: 1 | AM9: 2 | AN9: 3 | AO9: 4 | AP9: 1 | AQ9: 2 | AR9: 3 | AS9: 4 | AT9: 1 | AU9: 2 | AV9: 3 | AW9: 4 | AX9: 1 | AY9: 2 | AZ9: 3 | BA9: 4 | BB9: 1 | BC9: 2 | BD9: 3 | BE9: 4 | BG9: и.о.доцент | BH9: 900
A10: 4277 | B10: 2017 | C10: компьютерных технологий и электронного обучения | D10: Абрамян Геннадий Владимирович | E10: доктор педагогических наук | F10: профессор | G10: 1 | H10: 16005 | I10: Мультимедиа технологии и компьютерная графика | J10: 18 | L10: 54 | T10: 11 | W10: =IFERROR(OFFSET($AC$11,0,MATCH(H10,$AD$4:$BE$4,0)),IFERROR(OFFSET($AC$12,0,MATCH(H10,$AD$5:$BE$5,0)),MOD(H10,20)+7)) -> 12 | X10: =IF(W10<=30, "1", "2") -> 1 | Y10: =IF(W10<=15, "1", IF(W10<=30, "2", IF(W10<=45, "3", IF(W10<=60, "4")))) -> 1 | AA10: осн | AC10: год поступления | AD10: 2015 | AE10: 2014 | AF10: 2013 | AG10: 2012 | AH10: 2016 | AI10: 2015 | AJ10: 2014 | AK10: 2013 | AL10: 2017 | AM10: 2016 | AN10: 2015 | AO10: 2014 | AP10: 2018 | AQ10: 2017 | AR10: 2016 | AS10: 2015 | AT10: 2019 | AU10: 2018 | AV10: 2017 | AW10: 2016 | AX10: 2020 | AY10: 2019 | AZ10: 2018 | BA10: 2017 | BB10: 2021 | BC10: 2020 | BD10: 2019 | BE10: 2018 | BG10: внешний | BH10: 900
A11: 4277 | B11: 2018 | C11: компьютерных технологий и электронного обучения | D11: Абрамян Геннадий Владимирович | E11: доктор педагогических наук | F11: профессор | G11: 1 | H11: 17336 | I11: Мультимедиа технологии и компьютерная графика | L11: 36 | T11: 11 | W11: =IFERROR(OFFSET($AC$11,0,MATCH(H11,$AD$4:$BE$4,0)),IFERROR(OFFSET($AC$12,0,MATCH(H11,$AD$5:$BE$5,0)),MOD(H11,20)+7)) -> 23 | X11: =IF(W11<=30, "1", "2") -> 1 | Y11: =IF(W11<=15, "1", IF(W11<=30, "2", IF(W11<=45, "3", IF(W11<=60, "4")))) -> 2 | AA11: осн | AC11: Бакалавры (ИВТ) | AD11: 13 | AE11: 15 | AF11: 24 | AG11: 34 | AH11: 27 | AI11: 13 | AJ11: 56 | AK11: 55 | AL11: 29 | AM11: 27 | AN11: 13 | AO11: 23 | AP11: 39 | AQ11: 29 | AR11: 27 | AS11: 13 | AT11: 10 | AU11: 39 | AV11: 29 | AW11: 27 | AX11: 20 | AY11: 45 | AZ11: 29 | BA11: 27 | BB11: 20 | BC11: 45 | BD11: 48 | BE11: 39 | BG11: должность | BH11: 1
A12: 4699 | B12: 2016 | C12: компьютерных технологий и электронного обучения | D12: Полякова Наталия Александровна | E12: кандидат педагогических наук | F12: доцент | G12: 1 | H12: 15014 | I12: Информационные технологии | J12: 9 | K12: 32 | T12: 6 | W12: =IFERROR(OFFSET($AC$11,0,MATCH(H12,$AD$4:$BE$4,0)),IFERROR(OFFSET($AC$12,0,MATCH(H12,$AD$5:$BE$5,0)),MOD(H12,20)+7)) -> 21 | X12: =IF(W12<=30, "1", "2") -> 1 | Y12: =IF(W12<=15, "1", IF(W12<=30, "2", IF(W12<=45, "3", IF(W12<=60, "4")))) -> 2 | AA12: осн | AC12: Магистры (КЭО) | AD12: 10 | AE12: 23 | AH12: 56 | AI12: 34 | AL12: 10 | AM12: 10 | AP12: 10 | AQ12: 10 | AT12: 27 | AU12: 10 | AX12: 43 | AY12: 38 | BB12: 43 | BC12: 45 | BG12: должность | BH12: 1
A13: 4699 | B13: 2018 | C13: компьютерных технологий и электронного обучения | D13: Абрамян Геннадий Владимирович | E13: доктор педагогических наук | F13: профессор | G13: 1 | H13: 17337 | I13: Мультимедиа технологии и компьютерная графика | J13: 18 | L13: 54 | T13: 10 | W13: =IFERROR(OFFSET($AC$11,0,MATCH(H13,$AD$4:$BE$4,0)),IFERROR(OFFSET($AC$12,0,MATCH(H13,$AD$5:$BE$5,0)),MOD(H13,20)+7)) -> 24 | X13: =IF(W13<=30, "1", "2") -> 1 | Y13: =IF(W13<=15, "1", IF(W13<=30, "2", IF(W13<=45, "3", IF(W13<=60, "4")))) -> 2 | AA13: осн | BG13: должность | BH13: 1
A14: 4701 | B14: 2016 | C14: компьютерных технологий и электронного обучения | D14: Аксютин Павел Александрович | E14: нет | F14: ассистент | G14: 0.5 | H14: 15313 | I14: Информационные технологии | T14: 7 | W14: =IFERROR(OFFSET($AC$11,0,MATCH(H14,$AD$4:$BE$4,0)),IFERROR(OFFSET($AC$12,0,MATCH(H14,$AD$5:$BE$5,0)),MOD(H14,20)+7)) -> 20 | X14: =IF(W14<=30, "1", "2") -> 1 | Y14: =IF(W14<=15, "1", IF(W14<=30, "2", IF(W14<=45, "3", IF(W14<=60, "4")))) -> 2 | AA14: осн | BG14: должность | BH14: 1
A15: 4701 | B15: 2016 | C15: компьютерных технологий и электронного обучения | D15: Власова Елена Зотиковна | E15: доктор педагогических наук | F15: заведующий кафедрой | G15: 1 | H15: 15313 | I15: Информатика | J15: 2 | T15: 9 | W15: =IFERROR(OFFSET($AC$11,0,MATCH(H15,$AD$4:$BE$4,0)),IFERROR(OFFSET($AC$12,0,MATCH(H15,$AD$5:$BE$5,0)),MOD(H15,20)+7)) -> 20 | X15: =IF(W15<=30, "1", "2") -> 1 | Y15: =IF(W15<=15, "1", IF(W15<=30, "2", IF(W15<=45, "3", IF(W15<=60, "4")))) -> 2 | AA15: осн | BG15: должность | BH15: 1
A16: 4701 | B16: 2016 | C16: компьютерных технологий и электронного обучения | D16: Гончарова Светлана Викторовна | E16: кандидат педагогических наук | F16: доцент | G16: 1 | H16: 15313 | I16: Информатика | J16: 32 | L16: 51 | T16: 4 | W16: =IFERROR(OFFSET($AC$11,0,MATCH(H16,$AD$4:$BE$4,0)),IFERROR(OFFSET($AC$12,0,MATCH(H16,$AD$5:$BE$5,0)),MOD(H16,20)+7)) -> 20 | X16: =IF(W16<=30, "1", "2") -> 1 | Y16: =IF(W16<=15, "1", IF(W16<=30, "2", IF(W16<=45, "3", IF(W16<=60, "4")))) -> 2 | AA16: осн
A17: 4701 | B17: 2016 | C17: компьютерных технологий и электронного обучения | D17: Ильина Татьяна Сергеевна | E17: нет | F17: старший преподаватель | G17: 1 | H17: 15313 | I17: Информатика | L17: 102 | T17: 10 | W17: =IFERROR(OFFSET($AC$11,0,MATCH(H17,$AD$4:$BE$4,0)),IFERROR(OFFSET($AC$12,0,MATCH(H17,$AD$5:$BE$5,0)),MOD(H17,20)+7)) -> 20 | X17: =IF(W17<=30, "1", "2") -> 1 | Y17: =IF(W17<=15, "1", IF(W17<=30, "2", IF(W17<=45, "3", IF(W17<=60, "4")))) -> 2 | AA17: осн
A18: 4701 | B18: 2016 | C18: компьютерных технологий и электронного обучения | D18: Карпова Наталья Александровна | E18: кандидат технических наук | F18: доцент | G18: 0.5 | H18: 15313 | I18: Информационные технологии | J18: 17 | L18: 102 | T18: 12 | W18: =IFERROR(OFFSET($AC$11,0,MATCH(H18,$AD$4:$BE$4,0)),IFERROR(OFFSET($AC$12,0,MATCH(H18,$AD$5:$BE$5,0)),MOD(H18,20)+7)) -> 20 | X18: =IF(W18<=30, "1", "2") -> 1 | Y18: =IF(W18<=15, "1", IF(W18<=30, "2", IF(W18<=45, "3", IF(W18<=60, "4")))) -> 2 | AA18: осн
A19: 4755 | B19: 2016 | C19: компьютерных технологий и электронного обучения | D19: Абрамян Геннадий Владимирович | E19: доктор педагогических наук | F19: профессор | G19: 1 | H19: 15058 | I19: Информационное обеспечение технологического образования. Применение Интернет-технологий в технологическом образовании | J19: 18 | L19: 72 | T19: 17 | W19: =IFERROR(OFFSET($AC$11,0,MATCH(H19,$AD$4:$BE$4,0)),IFERROR(OFFSET($AC$12,0,MATCH(H19,$AD$5:$BE$5,0)),MOD(H19,20)+7)) -> 25 | X19: =IF(W19<=30, "1", "2") -> 1 | Y19: =IF(W19<=15, "1", IF(W19<=30, "2", IF(W19<=45, "3", IF(W19<=60, "4")))) -> 2 | AA19: осн
A20: 4755 | B20: 2016 | C20: компьютерных технологий и электронного обучения | D20: Авксентьева Елена Юрьевна | E20: кандидат педагогических наук | F20: доцент | G20: 1 | H20: 15058 | I20: Информационные технологии | K20: 96 | T20: 12 | W20: =IFERROR(OFFSET($AC$11,0,MATCH(H20,$AD$4:$BE$4,0)),IFERROR(OFFSET($AC$12,0,MATCH(H20,$AD$5:$BE$5,0)),MOD(H20,20)+7)) -> 25 | X20: =IF(W20<=30, "1", "2") -> 1 | Y20: =IF(W20<=15, "1", IF(W20<=30, "2", IF(W20<=45, "3", IF(W20<=60, "4")))) -> 2 | AA20: осн
A21: 4755 | B21: 2016 | C21: компьютерных технологий и электронного обучения | D21: Карпова Наталья Александровна | E21: кандидат технических наук | F21: доцент | G21: 1 | H21: 15058 | I21: Информационное обеспечение технологического образования. Применение Интернет-технологий в технологическом образовании | T21: 2 | W21: =IFERROR(OFFSET($AC$11,0,MATCH(H21,$AD$4:$BE$4,0)),IFERROR(OFFSET($AC$12,0,MATCH(H21,$AD$5:$BE$5,0)),MOD(H21,20)+7)) -> 25 | X21: =IF(W21<=30, "1", "2") -> 1 | Y21: =IF(W21<=15, "1", IF(W21<=30, "2", IF(W21<=45, "3", IF(W21<=60, "4")))) -> 2 | AA21: осн
A22: 4755 | B22: 2016 | C22: компьютерных технологий и электронного обучения | D22: Полякова Наталия Александровна | E22: кандидат педагогических наук | F22: доцент | G22: 1 | H22: 15058 | I22: Информационные технологии | J22: 9 | W22: =IFERROR(OFFSET($AC$11,0,MATCH(H22,$AD$4:$BE$4,0)),IFERROR(OFFSET($AC$12,0,MATCH(H22,$AD$5:$BE$5,0)),MOD(H22,20)+7)) -> 25 | X22: =IF(W22<=30, "1", "2") -> 1 | Y22: =IF(W22<=15, "1", IF(W22<=30, "2", IF(W22<=45, "3", IF(W22<=60, "4")))) -> 2 | AA22: осн
A23: 4755 | B23: 2017 | C23: компьютерных технологий и электронного обучения | D23: Готская Ирина Борисовна | E23: доктор педагогических наук | F23: профессор | G23: 1 | H23: 16007 | I23: Информационное обеспечение технологического образования. Применение электронных образовательных ресурсов в технологическом образовании | J23: 32 | L23: 160 | T23: 22 | W23: =IFERROR(OFFSET($AC$11,0,MATCH(H23,$AD$4:$BE$4,0)),IFERROR(OFFSET($AC$12,0,MATCH(H23,$AD$5:$BE$5,0)),MOD(H23,20)+7)) -> 14 | X23: =IF(W23<=30, "1", "2") -> 1 | Y23: =IF(W23<=15, "1", IF(W23<=30, "2", IF(W23<=45, "3", IF(W23<=60, "4")))) -> 1 | AA23: осн
A24: 4755 | B24: 2018 | C24: компьютерных технологий и электронного обучения | D24: Готская Ирина Борисовна | E24: доктор педагогических наук | F24: профессор | G24: 0.75 | H24: 17235 | I24: Информационное обеспечение технологического образования. Информационное обеспечение инновационной технологической деятельности | J24: 16 | L24: 80 | T24: 13 | W24: =IFERROR(OFFSET($AC$11,0,MATCH(H24,$AD$4:$BE$4,0)),IFERROR(OFFSET($AC$12,0,MATCH(H24,$AD$5:$BE$5,0)),MOD(H24,20)+7)) -> 22 | X24: =IF(W24<=30, "1", "2") -> 1 | Y24: =IF(W24<=15, "1", IF(W24<=30, "2", IF(W24<=45, "3", IF(W24<=60, "4")))) -> 2 | AA24: осн
A25: 4848 | B25: 2015 | C25: компьютерных технологий и электронного обучения | D25: Абрамян Геннадий Владимирович | E25: доктор педагогических наук | F25: профессор | G25: 1 | H25: 14014 | I25: ЭВМ и периферийные устройства | J25: 42 | L25: 42 | M25: 1 | N25: 1 | W25: =IFERROR(OFFSET($AC$11,0,MATCH(H25,$AD$4:$BE$4,0)),IFERROR(OFFSET($AC$12,0,MATCH(H25,$AD$5:$BE$5,0)),MOD(H25,20)+7)) -> 13 | X25: =IF(W25<=30, "1", "2") -> 1 | Y25: =IF(W25<=15, "1", IF(W25<=30, "2", IF(W25<=45, "3", IF(W25<=60, "4")))) -> 1 | AA25: осн
A26: 4848 | B26: 2015 | C26: компьютерных технологий и электронного обучения | D26: Власова Елена Зотиковна | E26: доктор педагогических наук | F26: заведующий кафедрой | G26: 1 | H26: 14014 | I26: Информатика | J26: 17 | K26: 17 | M26: 1 | N26: 1 | W26: =IFERROR(OFFSET($AC$11,0,MATCH(H26,$AD$4:$BE$4,0)),IFERROR(OFFSET($AC$12,0,MATCH(H26,$AD$5:$BE$5,0)),MOD(H26,20)+7)) -> 13 | X26: =IF(W26<=30, "1", "2") -> 1 | Y26: =IF(W26<=15, "1", IF(W26<=30, "2", IF(W26<=45, "3", IF(W26<=60, "4")))) -> 1 | AA26: осн
A27: 4848 | B27: 2015 | C27: компьютерных технологий и электронного обучения | D27: Власова Елена Зотиковна | E27: доктор педагогических наук | F27: заведующий кафедрой | G27: 1 | H27: 14014 | I27: Программирование | J27: 13 | L27: 23 | P27: 1 | W27: =IFERROR(OFFSET($AC$11,0,MATCH(H27,$AD$4:$BE$4,0)),IFERROR(OFFSET($AC$12,0,MATCH(H27,$AD$5:$BE$5,0)),MOD(H27,20)+7)) -> 13 | X27: =IF(W27<=30, "1", "2") -> 1 | Y27: =IF(W27<=15, "1", IF(W27<=30, "2", IF(W27<=45, "3", IF(W27<=60, "4")))) -> 1 | AA27: осн
A28: 4848 | B28: 2015 | C28: компьютерных технологий и электронного обучения | D28: Власова Елена Зотиковна | E28: доктор педагогических наук | F28: заведующий кафедрой | G28: 1 | H28: 14014 | I28: Модуль "ИТ в математике и физике" | M28: 1 | N28: 1 | W28: =IFERROR(OFFSET($AC$11,0,MATCH(H28,$AD$4:$BE$4,0)),IFERROR(OFFSET($AC$12,0,MATCH(H28,$AD$5:$BE$5,0)),MOD(H28,20)+7)) -> 13 | X28: =IF(W28<=30, "1", "2") -> 1 | Y28: =IF(W28<=15, "1", IF(W28<=30, "2", IF(W28<=45, "3", IF(W28<=60, "4")))) -> 1 | AA28: осн
A29: 4848 | B29: 2015 | C29: компьютерных технологий и электронного обучения | D29: Власова Елена Зотиковна | E29: доктор педагогических наук | F29: заведующий кафедрой | G29: 1 | H29: 14014 | I29: Модуль "ИТ в математике и физике". ИТ в физике | J29: 12 | W29: =IFERROR(OFFSET($AC$11,0,MATCH(H29,$AD$4:$BE$4,0)),IFERROR(OFFSET($AC$12,0,MATCH(H29,$AD$5:$BE$5,0)),MOD(H29,20)+7)) -> 13 | X29: =IF(W29<=30, "1", "2") -> 1 | Y29: =IF(W29<=15, "1", IF(W29<=30, "2", IF(W29<=45, "3", IF(W29<=60, "4")))) -> 1 | AA29: осн
A30: 4848 | B30: 2015 | C30: компьютерных технологий и электронного обучения | D30: Гончарова Светлана Викторовна | E30: кандидат педагогических наук | F30: доцент | G30: 1 | H30: 14014 | I30: Информатика | L30: 34 | W30: =IFERROR(OFFSET($AC$11,0,MATCH(H30,$AD$4:$BE$4,0)),IFERROR(OFFSET($AC$12,0,MATCH(H30,$AD$5:$BE$5,0)),MOD(H30,20)+7)) -> 13 | X30: =IF(W30<=30, "1", "2") -> 1 | Y30: =IF(W30<=15, "1", IF(W30<=30, "2", IF(W30<=45, "3", IF(W30<=60, "4")))) -> 1 | AA30: осн
A31: 4848 | B31: 2015 | C31: компьютерных технологий и электронного обучения | D31: Гончарова Светлана Викторовна | E31: кандидат педагогических наук | F31: доцент | G31: 1 | H31: 14014 | I31: Модуль "ИТ в математике и физике" | N31: 1 | W31: =IFERROR(OFFSET($AC$11,0,MATCH(H31,$AD$4:$BE$4,0)),IFERROR(OFFSET($AC$12,0,MATCH(H31,$AD$5:$BE$5,0)),MOD(H31,20)+7)) -> 13 | X31: =IF(W31<=30, "1", "2") -> 1 | Y31: =IF(W31<=15, "1", IF(W31<=30, "2", IF(W31<=45, "3", IF(W31<=60, "4")))) -> 1 | AA31: осн
A32: 4848 | B32: 2015 | C32: компьютерных технологий и электронного обучения | D32: Гончарова Светлана Викторовна | E32: кандидат педагогических наук | F32: доцент | G32: 1 | H32: 14014 | I32: Модуль "ИТ в математике и физике". ИТ в физике | L32: 24 | P32: 1 | W32: =IFERROR(OFFSET($AC$11,0,MATCH(H32,$AD$4:$BE$4,0)),IFERROR(OFFSET($AC$12,0,MATCH(H32,$AD$5:$BE$5,0)),MOD(H32,20)+7)) -> 13 | X32: =IF(W32<=30, "1", "2") -> 1 | Y32: =IF(W32<=15, "1", IF(W32<=30, "2", IF(W32<=45, "3", IF(W32<=60, "4")))) -> 1 | AA32: осн
A33: 4848 | B33: 2015 | C33: компьютерных технологий и электронного обучения | D33: Гончарова Светлана Викторовна | E33: кандидат педагогических наук | F33: доцент | G33: 1 | H33: 14014 | I33: Программирование | J33: 14 | L33: 22 | P33: 1 | W33: =IFERROR(OFFSET($AC$11,0,MATCH(H33,$AD$4:$BE$4,0)),IFERROR(OFFSET($AC$12,0,MATCH(H33,$AD$5:$BE$5,0)),MOD(H33,20)+7)) -> 13 | X33: =IF(W33<=30, "1", "2") -> 1 | Y33: =IF(W33<=15, "1", IF(W33<=30, "2", IF(W33<=45, "3", IF(W33<=60, "4")))) -> 1 | AA33: осн
A34: 4848 | B34: 2015 | C34: компьютерных технологий и электронного обучения | D34: Государев Илья Борисович | E34: кандидат педагогических наук | F34: доцент | G34: 1 | H34: 14014 | I34: Информационные технологии в изучении иностранных языков | J34: 6 | L34: 12 | P34: 1 | W34: =IFERROR(OFFSET($AC$11,0,MATCH(H34,$AD$4:$BE$4,0)),IFERROR(OFFSET($AC$12,0,MATCH(H34,$AD$5:$BE$5,0)),MOD(H34,20)+7)) -> 13 | X34: =IF(W34<=30, "1", "2") -> 1 | Y34: =IF(W34<=15, "1", IF(W34<=30, "2", IF(W34<=45, "3", IF(W34<=60, "4")))) -> 1 | AA34: осн
A35: 4848 | B35: 2015 | C35: компьютерных технологий и электронного обучения | D35: Государев Илья Борисович | E35: кандидат педагогических наук | F35: доцент | G35: 1 | H35: 14014 | I35: Модуль "Дискретные структуры" | M35: 1 | N35: 1 | W35: =IFERROR(OFFSET($AC$11,0,MATCH(H35,$AD$4:$BE$4,0)),IFERROR(OFFSET($AC$12,0,MATCH(H35,$AD$5:$BE$5,0)),MOD(H35,20)+7)) -> 13 | X35: =IF(W35<=30, "1", "2") -> 1 | Y35: =IF(W35<=15, "1", IF(W35<=30, "2", IF(W35<=45, "3", IF(W35<=60, "4")))) -> 1 | AA35: осн
A36: 4848 | B36: 2015 | C36: компьютерных технологий и электронного обучения | D36: Государев Илья Борисович | E36: кандидат педагогических наук | F36: доцент | G36: 1 | H36: 14014 | I36: Модуль "Дискретные структуры". Дискретная математика | J36: 17 | K36: 17 | W36: =IFERROR(OFFSET($AC$11,0,MATCH(H36,$AD$4:$BE$4,0)),IFERROR(OFFSET($AC$12,0,MATCH(H36,$AD$5:$BE$5,0)),MOD(H36,20)+7)) -> 13 | X36: =IF(W36<=30, "1", "2") -> 1 | Y36: =IF(W36<=15, "1", IF(W36<=30, "2", IF(W36<=45, "3", IF(W36<=60, "4")))) -> 1 | AA36: осн
A37: 4848 | B37: 2015 | C37: компьютерных технологий и электронного обучения | D37: Государев Илья Борисович | E37: кандидат педагогических наук | F37: доцент | G37: 1 | H37: 14014 | I37: Модуль "Дискретные структуры". Алгоритмы и анализ сложности | J37: 9 | K37: 9 | W37: =IFERROR(OFFSET($AC$11,0,MATCH(H37,$AD$4:$BE$4,0)),IFERROR(OFFSET($AC$12,0,MATCH(H37,$AD$5:$BE$5,0)),MOD(H37,20)+7)) -> 13 | X37: =IF(W37<=30, "1", "2") -> 1 | Y37: =IF(W37<=15, "1", IF(W37<=30, "2", IF(W37<=45, "3", IF(W37<=60, "4")))) -> 1 | AA37: осн
A38: 4848 | B38: 2015 | C38: компьютерных технологий и электронного обучения | D38: Ильина Татьяна Сергеевна | E38: нет | F38: старший преподаватель | G38: 1 | H38: 14014 | I38: Математика | J38: 54 | K38: 54 | M38: 1 | N38: 1 | W38: =IFERROR(OFFSET($AC$11,0,MATCH(H38,$AD$4:$BE$4,0)),IFERROR(OFFSET($AC$12,0,MATCH(H38,$AD$5:$BE$5,0)),MOD(H38,20)+7)) -> 13 | X38: =IF(W38<=30, "1", "2") -> 1 | Y38: =IF(W38<=15, "1", IF(W38<=30, "2", IF(W38<=45, "3", IF(W38<=60, "4")))) -> 1 | AA38: осн
A39: 4848 | B39: 2015 | C39: компьютерных технологий и электронного обучения | D39: Ильина Татьяна Сергеевна | E39: нет | F39: старший преподаватель | G39: 1 | H39: 14014 | I39: Модуль "ИТ в математике и физике". Информационные технологии в математике | L39: 36 | W39: =IFERROR(OFFSET($AC$11,0,MATCH(H39,$AD$4:$BE$4,0)),IFERROR(OFFSET($AC$12,0,MATCH(H39,$AD$5:$BE$5,0)),MOD(H39,20)+7)) -> 13 | X39: =IF(W39<=30, "1", "2") -> 1 | Y39: =IF(W39<=15, "1", IF(W39<=30, "2", IF(W39<=45, "3", IF(W39<=60, "4")))) -> 1 | AA39: осн
A40: 4848 | B40: 2016 | C40: компьютерных технологий и электронного обучения | D40: Абрамян Геннадий Владимирович | E40: доктор педагогических наук | F40: профессор | G40: 1 | H40: 15377 | I40: Базы данных | J40: 36 | K40: 12 | L40: 26 | M40: 1 | N40: 1 | W40: =IFERROR(OFFSET($AC$11,0,MATCH(H40,$AD$4:$BE$4,0)),IFERROR(OFFSET($AC$12,0,MATCH(H40,$AD$5:$BE$5,0)),MOD(H40,20)+7)) -> 13 | X40: =IF(W40<=30, "1", "2") -> 1 | Y40: =IF(W40<=15, "1", IF(W40<=30, "2", IF(W40<=45, "3", IF(W40<=60, "4")))) -> 1 | AA40: осн
...

Sheet Данные, контроль
J1: Лекции | K1: Практ. | L1: Лаб.р. | M1: конс. | N1: экз | O1: диф.зач | P1: зач | Q1: курсов.р | R1: ГЭК (защита) | S1: ГЭК (экзамен) | T1: Контроль | U1: Практики | V1: Рук-во | AB1: Стандарт часов в год | AC1: Бакалавры ИВТ / магистры КЭО | AD1: Учебный год | AE1: Сумма часов | AF1: Объём учебной нагрузки (доля ставки) | AG1: Сумма долей работодателей | AH1: Процент работодателей от общей суммы часов | AJ1: учебный год | AK1: 2015/2016 | AO1: 2016/2017 | AS1: 2017/2018 | AW1: 2018/2019 | BA1: 2019/2020 | BE1: 2020/2021 | BI1: 2021/2022 | BN1: Стандарт часов по должностям | BQ1: Абдуллаева Любовь Магомедовна | BR1: Абрамян Геннадий Владимирович | BS1: Авксентьева Елена Юрьевна | BT1: Акимов Станислав Сергеевич | BU1: Аксютин Павел Александрович | BV1: Атаян Ануш Михайловна | BW1: Байгузева Александра Петровна | BX1: Барченко Сергей Алексеевич | BY1: Бендюкова Татьяна Савельевна | BZ1: Богатова Елена Владимировна | CA1: Бочковская Виктория Леонидовна | CB1: Васильев Сергей Васильевич | CC1: Василькова Ирина Генриховна | CD1: Васютина Ирина Павловна | CE1: Власов Дмитрий Викторович | CF1: Власова Елена Зотиковна | CG1: Воробьев Владимир Иванович | CH1: Гасумянц Виталий Эдуардович | CI1: Гончарко Дмитрий Николаевич | CJ1: Гончарова Светлана Викторовна | CK1: Государев Илья Борисович | CL1: Готская Ирина Борисовна | CM1: Дулин Юрий Николаевич | CN1: Еремина Нелли Владимировна | CO1: Ерошкина Ольга Николаевна | CP1: Есипова Александра Анатольевна | CQ1: Жаркой Александр Борисович | CR1: Жуков Николай Николаевич | CS1: Жукова Татьяна Викторовна | CT1: Земляницин Владимир Александрович | CU1: Зюкин Анатолий Васильевич | CV1: Иванова Екатерина Алексеевна | CW1: Ильина Татьяна Сергеевна | CX1: Карпова Наталья Александровна | CY1: Качоровская Анна Евгеньевна | CZ1: Колдунов Андрей Витальевич | DA1: Кондаков Юрий Евгеньевич | DB1: Копыльцов Александр Васильевич | DC1: Косова Ирина Святославна | DD1: Кравченко Наталия Николаевна | DE1: Кудрявцева Наталья Фаддеевна | DF1: Кужельная Оксана Владимировна | DG1: Кузнецова Надежда Леонидовна | DH1: Лапина Ирина Александровна | DI1: Левина Ирина Николаевна | DJ1: Лужков Александр Альбертович | DK1: Любимов Александр Владимирович | DL1: Маслов Вадим Владимирович | DM1: Матюшичев Илья Юрьевич | DN1: Михайлов Александр Борисович | DO1: Николаева Наталья Викторовна | DP1: Пальтиель Лев Романович | DQ1: Пантелеева Людмила Валентиновна | DR1: Певзнер Игорь Михайлович | DS1: Пентина Анна Юрьевна | DT1: Полякова Наталия Александровна | DU1: Порязь Надежда Вадимовна | DV1: Поспелов Михаил Владимирович | DW1: Пую Юлия Валерьевна | DX1: Разуваев Николай Викторович | DY1: Райкова Вера Алексеевна | DZ1: Рудаков Леонид Ильич | EA1: Серегин Александр Николаевич | EB1: Серегин Павел Павлович | EC1: Силантьев Евгений Евгеньевич | ED1: Смирнов Александр Михайлович | EE1: Тарамжина Людмила Витольдовна | EF1: Тихонова Анастасия Михайловна | EG1: Хахалина Марина Сергеевна | EH1: Хинич Иосиф Исаакович | EI1: Шалденкова Анна Владимировна | EJ1: Шангин Андрей Борисович | EK1: Швецкий Михаил Владимирович | EL1: Швинк Лоренс Ричард
A2: Код УП | B2: Год нагрузки | C2: Кафедра | D2: ФИО | E2: Степень | F2: Должность | G2: Ставка | H2: Код РУП | I2: Дисциплина / практика / ВКР / ГИА | J2: Часы | W2: Студ. | X2: Количество групп | Y2: Количество подгрупп | Z2: Специальность | AA2: Вид нагрузки | AF2: =SUM(AF3:AF862) -> 62.425923 | AJ2: курс | AK2: 1 | AL2: 2 | AM2: 3 | AN2: 4 | AO2: 1 | AP2: 2 | AQ2: 3 | AR2: 4 | AS2: 1 | AT2: 2 | AU2: 3 | AV2: 4 | AW2: 1 | AX2: 2 | AY2: 3 | AZ2: 4 | BA2: 1 | BB2: 2 | BC2: 3 | BD2: 4 | BE2: 1 | BF2: 2 | BG2: 3 | BH2: 4 | BI2: 1 | BJ2: 2 | BK2: 3 | BL2: 4 | BN2: Должность | BO2: Часы | BQ2: 0 | BR2: 0 | BS2: 0 | BT2: 0 | BU2: 0 | BV2: 0 | BW2: 0 | BX2: 0 | BY2: 0 | BZ2: 0 | CA2: 0 | CB2: 0 | CC2: 0 | CD2: 0 | CE2: 0 | CF2: 0 | CG2: 0 | CH2: 0 | CI2: 0 | CJ2: 0 | CK2: 0 | CL2: 0 | CM2: 0 | CN2: 0 | CO2: 0 | CP2: 0 | CQ2: 0 | CR2: 0 | CS2: 0 | CT2: 0 | CU2: 0 | CV2: 0 | CW2: 0 | CX2: 0 | CY2: 0 | CZ2: 0 | DA2: 0 | DB2: 0 | DC2: 0 | DD2: 0 | DE2: 0 | DF2: 0 | DG2: 0 | DH2: 0 | DI2: 0 | DJ2: 0 | DK2: 0 | DL2: 0 | DM2: 0 | DN2: 0 | DO2: 0 | DP2: 0 | DQ2: 0 | DR2: 0 | DS2: 0 | DT2: 0 | DU2: 0 | DV2: 0 | DW2: 0 | DX2: 0 | DY2: 0 | DZ2: 0 | EA2: 0 | EB2: 0 | EC2: 0 | ED2: 0 | EE2: 0 | EF2: 0 | EG2: 0 | EH2: 0 | EI2: 0 | EJ2: 0 | EK2: 0 | EL2: 0
A3: =Данные!A3 -> 3250 | B3: =Данные!B3 -> 2015 | C3: =Данные!C3 -> компьютерных технологий и электронного обучения | D3: =Данные!D3 -> Гончарова Светлана Викторовна | E3: =Данные!E3 -> кандидат педагогических наук | F3: =Данные!F3 -> доцент | G3: =Данные!G3 -> 1 | H3: =Данные!H3 -> 13809 | ... L3: =Данные!L3 -> 102 | M3: =SUM(J3:L3)/10 -> 13.6 | N3: =2+(0.33*W3) -> 7.28 | O3: =0.25*W3 -> 4 | P3: =0.25*W3 -> 4 | Q3: =Данные!Q3 -> 0 | R3: =Данные!R3 -> 0 | S3: =Данные!S3 -> 0 | T3: =Данные!T3 -> 12 | U3: =Данные!U3 -> 0 | V3: =Данные!V3 -> 0 | W3: =Данные!W3 -> 16 | X3: =Данные!X3 -> 1 | ... AA3: =Данные!AA3 -> осн | AB3: =VLOOKUP(F3, $BN$3:$BO$15, 2, 0) -> 800 | AC3: =IF(IFERROR(MATCH(H3, $AK$4:$BL$4, 0), 0)>=1, "ИВТ (бак)", IF(IFERROR(MATCH(H3, $AK$5:$BL$5, 0), 0)>=1, "КЭО (маг)", "")) | AD3: =IF(IFERROR(MATCH(H3, $AK$4:$AN$4, 0), 0)=1, "2015–2016", IF(IFERROR(MATCH(H3, $AO$4:$AR$4, 0), 0)=1, "2016–2017", IF(IFERROR(MATCH(H3, $AS$4:$AV$4, 0), 0)=1, "2017–2018", IF(IFERROR(MATCH(H3, $AW$4:$AZ$4, 0), 0)=1, "2018–2019", IF(IFERROR(MATCH(H3, $BA$4:$BD$4, 0), 0)=1, "2019–2020", IF(IFERROR(MATCH(H3, $BE$4:$BH$4, 0), 0)=1, "2020–2021", IF(IFERROR(MATCH(H3, $BI$4:$BL$4, 0), 0)=1, "2021–2022", ""))))))) | AE3: =SUM(J3:V3) -> 176.88 | AF3: =AE3/AB3 -> 0.2211 | AJ3: год поступления | AK3: 2015 | AL3: 2014 | AM3: 2013 | AN3: 2012 | AO3: 2016 | AP3: 2015 | AQ3: 2014 | AR3: 2013 | AS3: 2017 | AT3: 2016 | AU3: 2015 | AV3: 2014 | AW3: 2018 | AX3: 2017 | AY3: 2016 | AZ3: 2015 | BA3: 2019 | BB3: 2018 | BC3: 2017 | BD3: 2016 | BE3: 2020 | BF3: 2019 | BG3: 2018 | BH3: 2017 | BI3: 2021 | BJ3: 2020 | BK3: 2019 | BL3: 2018 | BN3: =Данные!BG3 -> заведующий кафедрой | BO3: =Данные!BH3 -> 700 | BQ3: 0 | BR3: 0 | BS3: 0 | BT3: 0 | BU3: 0 | BV3: 0 | BW3: 0 | BX3: 0 | BY3: 0 | BZ3: 0 | CA3: 0 | CB3: 0 | CC3: 0 | CD3: 0 | CE3: 0 | CF3: 0 | CG3: 0 | CH3: 0 | CI3: 0 | CJ3: 0 | CK3: 0 | CL3: 0 | CM3: 0 | CN3: 0 | CO3: 0 | CP3: 0 | CQ3: 0 | CR3: 0 | CS3: 0 | CT3: 0 | CU3: 0 | CV3: 0 | CW3: 0 | CX3: 0 | CY3: 0 | CZ3: 0 | DA3: 0 | DB3: 0 | DC3: 0 | DD3: 0 | DE3: 0 | DF3: 0 | DG3: 0 | DH3: 0 | DI3: 0 | DJ3: 0 | DK3: 0 | DL3: 0 | DM3: 0 | DN3: 0 | DO3: 0 | DP3: 0 | DQ3: 0 | DR3: 0 | DS3: 0 | DT3: 0 | DU3: 0 | DV3: 0 | DW3: 0 | DX3: 0 | DY3: 0 | DZ3: 0 | EA3: 0 | EB3: 0 | EC3: 0 | ED3: 0 | EE3: 0 | EF3: 0 | EG3: 0 | EH3: 0 | EI3: 0 | EJ3: 0 | EK3: 0 | EL3: 0
A4: =Данные!A4 -> 4276 | B4: =Данные!B4 -> 2015 | C4: =Данные!C4 -> компьютерных технологий и электронного обучения | D4: =Данные!D4 -> Абрамян Геннадий Владимирович | E4: =Данные!E4 -> доктор педагогических наук | F4: =Данные!F4 -> профессор | G4: =Данные!G4 -> 1 | H4: =Данные!H4 -> 13818 | ... L4: =Данные!L4 -> 54 | M4: =SUM(J4:L4)/10 -> 7.2 | N4: =2+(0.33*W4) -> 10.25 | O4: =0.25*W4 -> 6.25 | P4: =0.25*W4 -> 6.25 | Q4: =Данные!Q4 -> 0 | R4: =Данные!R4 -> 0 | S4: =Данные!S4 -> 0 | T4: =Данные!T4 -> 21 | U4: =Данные!U4 -> 0 | V4: =Данные!V4 -> 0 | W4: =Данные!W4 -> 25 | X4: =Данные!X4 -> 1 | ... AA4: =Данные!AA4 -> осн | AB4: =VLOOKUP(F4, $BN$3:$BO$15, 2, 0) -> 750 | AC4: =IF(IFERROR(MATCH(H4, $AK$4:$BL$4, 0), 0)>=1, "ИВТ (бак)", IF(IFERROR(MATCH(H4, $AK$5:$BL$5, 0), 0)>=1, "КЭО (маг)", "")) | AD4: =IF(IFERROR(MATCH(H4, $AK$4:$AN$4, 0), 0)=1, "2015–2016", IF(IFERROR(MATCH(H4, $AO$4:$AR$4, 0), 0)=1, "2016–2017", IF(IFERROR(MATCH(H4, $AS$4:$AV$4, 0), 0)=1, "2017–2018", IF(IFERROR(MATCH(H4, $AW$4:$AZ$4, 0), 0)=1, "2018–2019", IF(IFERROR(MATCH(H4, $BA$4:$BD$4, 0), 0)=1, "2019–2020", IF(IFERROR(MATCH(H4, $BE$4:$BH$4, 0), 0)=1, "2020–2021", IF(IFERROR(MATCH(H4, $BI$4:$BL$4, 0), 0)=1, "2021–2022", ""))))))) | AE4: =SUM(J4:V4) -> 122.95 | AF4: =AE4/AB4 -> 0.16393333 | AJ4: Бакалавры (ИВТ) | AK4: =Данные!AD4 -> 14014 | AL4: =Данные!AE4 -> 24098 | AM4: =Данные!AF4 -> 11090 | AN4: =Данные!AG4 -> 12090 | AO4: =Данные!AH4 -> 15177 | AP4: =Данные!AI4 -> 15377 | AQ4: =Данные!AJ4 -> 25432 | AR4: =Данные!AK4 -> 23456 | ... BL4: =Данные!BE4 -> 4 курс 2018 год/пост | BN4: =Данные!BG4 -> профессор | BO4: =Данные!BH4 -> 750 | BQ4: 0 | BR4: 0 | BS4: 0 | BT4: 0 | BU4: 0 | BV4: 0 | BW4: 0 | BX4: 0 | BY4: 0 | BZ4: 0 | CA4: 0 | CB4: 0 | CC4: 0 | CD4: 0 | CE4: 0 | CF4: 0 | CG4: 0 | CH4: 0 | CI4: 0 | CJ4: 0 | CK4: 0 | CL4: 0 | CM4: 0 | CN4: 0 | CO4: 0 | CP4: 0 | CQ4: 0 | CR4: 0 | CS4: 0 | CT4: 0 | CU4: 0 | CV4: 0 | CW4: 0 | CX4: 0 | CY4: 0 | CZ4: 0 | DA4: 0 | DB4: 0 | DC4: 0 | DD4: 0 | DE4: 0 | DF4: 0 | DG4: 0 | DH4: 0 | DI4: 0 | DJ4: 0 | DK4: 0 | DL4: 0 | DM4: 0 | DN4: 0 | DO4: 0 | DP4: 0 | DQ4: 0 | DR4: 0 | DS4: 0 | DT4: 0 | DU4: 0 | DV4: 0 | DW4: 0 | DX4: 0 | DY4: 0 | DZ4: 0 | EA4: 0 | EB4: 0 | EC4: 0 | ED4: 0 | EE4: 0 | EF4: 0 | EG4: 0 | EH4: 0 | EI4: 0 | EJ4: 0 | EK4: 0 | EL4: 0
A5: =Данные!A5 -> 4276 | B5: =Данные!B5 -> 2015 | C5: =Данные!C5 -> компьютерных технологий и электронного обучения | D5: =Данные!D5 -> Авксентьева Елена Юрьевна | E5: =Данные!E5 -> кандидат педагогических наук | F5: =Данные!F5 -> доцент | G5: =Данные!G5 -> 1 | H5: =Данные!H5 -> 13818 | ... L5: =Данные!L5 -> 0 | M5: =SUM(J5:L5)/10 -> 0 | N5: =2+(0.33*W5) -> 10.25 | O5: =0.25*W5 -> 6.25 | P5: =0.25*W5 -> 6.25 | Q5: =Данные!Q5 -> 0 | R5: =Данные!R5 -> 0 | S5: =Данные!S5 -> 0 | T5: =Данные!T5 -> 15 | U5: =Данные!U5 -> 0 | V5: =Данные!V5 -> 0 | W5: =Данные!W5 -> 25 | X5: =Данные!X5 -> 1 | ... AA5: =Данные!AA5 -> осн | AB5: =VLOOKUP(F5, $BN$3:$BO$15, 2, 0) -> 800 | AC5: =IF(IFERROR(MATCH(H5, $AK$4:$BL$4, 0), 0)>=1, "ИВТ (бак)", IF(IFERROR(MATCH(H5, $AK$5:$BL$5, 0), 0)>=1, "КЭО (маг)", "")) | AD5: =IF(IFERROR(MATCH(H5, $AK$4:$AN$4, 0), 0)=1, "2015–2016", IF(IFERROR(MATCH(H5, $AO$4:$AR$4, 0), 0)=1, "2016–2017", IF(IFERROR(MATCH(H5, $AS$4:$AV$4, 0), 0)=1, "2017–2018", IF(IFERROR(MATCH(H5, $AW$4:$AZ$4, 0), 0)=1, "2018–2019", IF(IFERROR(MATCH(H5, $BA$4:$BD$4, 0), 0)=1, "2019–2020", IF(IFERROR(MATCH(H5, $BE$4:$BH$4, 0), 0)=1, "2020–2021", IF(IFERROR(MATCH(H5, $BI$4:$BL$4, 0), 0)=1, "2021–2022", ""))))))) | AE5: =SUM(J5:V5) -> 37.75 | AF5: =AE5/AB5 -> 0.0471875 | AJ5: Магистры (КЭО) | AK5: =Данные!AD5 -> 14020 | AL5: =Данные!AE5 -> 34567 | AO5: =Данные!AH5 -> 34789 | AP5: =Данные!AI5 -> 12987 | AS5: =Данные!AL5 -> 16595 | AT5: =Данные!AM5 -> 15764 | AW5: =Данные!AP5 -> 17048 | AX5: =Данные!AQ5 -> 17248 | BA5: =Данные!AT5 -> 18945 | BB5: =Данные!AU5 -> 2 курс (м) 2018 год/пост | BE5: =Данные!AX5 -> 23900 | BF5: =Данные!AY5 -> 15999 | BI5: =Данные!BB5 -> 12000 | BJ5: =Данные!BC5 -> 24000 | BN5: =Данные!BG5 -> доцент | BO5: =Данные!BH5 -> 800 | BQ5: 0 | BR5: 0 | BS5: 0 | BT5: 0 | BU5: 0 | BV5: 0 | BW5: 0 | BX5: 0 | BY5: 0 | BZ5: 0 | CA5: 0 | CB5: 0 | CC5: 0 | CD5: 0 | CE5: 0 | CF5: 0 | CG5: 0 | CH5: 0 | CI5: 0 | CJ5: 0 | CK5: 0 | CL5: 0 | CM5: 0 | CN5: 0 | CO5: 0 | CP5: 0 | CQ5: 0 | CR5: 0 | CS5: 0 | CT5: 0 | CU5: 0 | CV5: 0 | CW5: 0 | CX5: 0 | CY5: 0 | CZ5: 0 | DA5: 0 | DB5: 0 | DC5: 0 | DD5: 0 | DE5: 0 | DF5: 0 | DG5: 0 | DH5: 0 | DI5: 0 | DJ5: 0 | DK5: 0 | DL5: 0 | DM5: 0 | DN5: 0 | DO5: 0 | DP5: 0 | DQ5: 0 | DR5: 0 | DS5: 0 | DT5: 0 | DU5: 0 | DV5: 0 | DW5: 0 | DX5: 0 | DY5: 0 | DZ5: 0 | EA5: 0 | EB5: 0 | EC5: 0 | ED5: 0 | EE5: 0 | EF5: 0 | EG5: 0 | EH5: 0 | EI5: 0 | EJ5: 0 | EK5: 0 | EL5: 0
A6: =Данные!A6 -> 4276 | B6: =Данные!B6 -> 2015 | C6: =Данные!C6 -> компьютерных технологий и электронного обучения | D6: =Данные!D6 -> Гончарова Светлана Викторовна | E6: =Данные!E6 -> кандидат педагогических наук | F6: =Данные!F6 -> доцент | G6: =Данные!G6 -> 1 | H6: =Данные!H6 -> 13818 | ... L6: =Данные!L6 -> 0 | M6: =SUM(J6:L6)/10 -> 4.1 | N6: =2+(0.33*W6) -> 10.25 | O6: =0.25*W6 -> 6.25 | P6: =0.25*W6 -> 6.25 | Q6: =Данные!Q6 -> 0 | R6: =Данные!R6 -> 0 | S6: =Данные!S6 -> 0 | T6: =Данные!T6 -> 3 | U6: =Данные!U6 -> 0 | V6: =Данные!V6 -> 0 | W6: =Данные!W6 -> 25 | X6: =Данные!X6 -> 1 | ... AA6: =Данные!AA6 -> осн | AB6: =VLOOKUP(F6, $BN$3:$BO$15, 2, 0) -> 800 | AC6: =IF(IFERROR(MATCH(H6, $AK$4:$BL$4, 0), 0)>=1, "ИВТ (бак)", IF(IFERROR(MATCH(H6, $AK$5:$BL$5, 0), 0)>=1, "КЭО (маг)", "")) | AD6: =IF(IFERROR(MATCH(H6, $AK$4:$AN$4, 0), 0)=1, "2015–2016", IF(IFERROR(MATCH(H6, $AO$4:$AR$4, 0), 0)=1, "2016–2017", IF(IFERROR(MATCH(H6, $AS$4:$AV$4, 0), 0)=1, "2017–2018", IF(IFERROR(MATCH(H6, $AW$4:$AZ$4, 0), 0)=1, "2018–2019", IF(IFERROR(MATCH(H6, $BA$4:$BD$4, 0), 0)=1, "2019–2020", IF(IFERROR(MATCH(H6, $BE$4:$BH$4, 0), 0)=1, "2020–2021", IF(IFERROR(MATCH(H6, $BI$4:$BL$4, 0), 0)=1, "2021–2022", ""))))))) | AE6: =SUM(J6:V6) -> 70.85 | AF6: =AE6/AB6 -> 0.0885625 | BN6: =Данные!BG6 -> старший преподаватель | BO6: =Данные!BH6 -> 850 | BQ6: 0 | BR6: 0 | BS6: 0 | BT6: 0 | BU6: 0 | BV6: 0 | BW6: 0 | BX6: 0 | BY6: 0 | BZ6: 0 | CA6: 0 | CB6: 0 | CC6: 0 | CD6: 0 | CE6: 0 | CF6: 0 | CG6: 0 | CH6: 0 | CI6: 0 | CJ6: 0 | CK6: 0 | CL6: 0 | CM6: 0 | CN6: 0 | CO6: 0 | CP6: 0 | CQ6: 0 | CR6: 0 | CS6: 0 | CT6: 0 | CU6: 0 | CV6: 0 | CW6: 0 | CX6: 0 | CY6: 0 | CZ6: 0 | DA6: 0 | DB6: 0 | DC6: 0 | DD6: 0 | DE6: 0 | DF6: 0 | DG6: 0 | DH6: 0 | DI6: 0 | DJ6: 0 | DK6: 0 | DL6: 0 | DM6: 0 | DN6: 0 | DO6: 0 | DP6: 0 | DQ6: 0 | DR6: 0 | DS6: 0 | DT6: 0 | DU6: 0 | DV6: 0 | DW6: 0 | DX6: 0 | DY6: 0 | DZ6: 0 | EA6: 0 | EB6: 0 | EC6: 0 | ED6: 0 | EE6: 0 | EF6: 0 | EG6: 0 | EH6: 0 | EI6: 0 | EJ6: 0 | EK6: 0 | EL6: 0
A7: =Данные!A7 -> 4276 | B7: =Данные!B7 -> 2015 | C7: =Данные!C7 -> компьютерных технологий и электронного обучения | D7: =Данные!D7 -> Ильина Татьяна Сергеевна | E7: =Данные!E7 -> нет | F7: =Данные!F7 -> старший преподаватель | G7: =Данные!G7 -> 1 | H7: =Данные!H7 -> 13818 | ... L7: =Данные!L7 -> 0 | M7: =SUM(J7:L7)/10 -> 6.4 | N7: =2+(0.33*W7) -> 10.25 | O7: =0.25*W7 -> 6.25 | P7: =0.25*W7 -> 6.25 | Q7: =Данные!Q7 -> 0 | R7: =Данные!R7 -> 0 | S7: =Данные!S7 -> 0 | T7: =Данные!T7 -> 3 | U7: =Данные!U7 -> 0 | V7: =Данные!V7 -> 0 | W7: =Данные!W7 -> 25 | X7: =Данные!X7 -> 1 | ... AA7: =Данные!AA7 -> осн | AB7: =VLOOKUP(F7, $BN$3:$BO$15, 2, 0) -> 850 | AC7: =IF(IFERROR(MATCH(H7, $AK$4:$BL$4, 0), 0)>=1, "ИВТ (бак)", IF(IFERROR(MATCH(H7, $AK$5:$BL$5, 0), 0)>=1, "КЭО (маг)", "")) | AD7: =IF(IFERROR(MATCH(H7, $AK$4:$AN$4, 0), 0)=1, "2015–2016", IF(IFERROR(MATCH(H7, $AO$4:$AR$4, 0), 0)=1, "2016–2017", IF(IFERROR(MATCH(H7, $AS$4:$AV$4, 0), 0)=1, "2017–2018", IF(IFERROR(MATCH(H7, $AW$4:$AZ$4, 0), 0)=1, "2018–2019", IF(IFERROR(MATCH(H7, $BA$4:$BD$4, 0), 0)=1, "2019–2020", IF(IFERROR(MATCH(H7, $BE$4:$BH$4, 0), 0)=1, "2020–2021", IF(IFERROR(MATCH(H7, $BI$4:$BL$4, 0), 0)=1, "2021–2022", ""))))))) | AE7: =SUM(J7:V7) -> 96.15 | AF7: =AE7/AB7 -> 0.11311765 | BN7: =Данные!BG7 -> ассистент | BO7: =Данные!BH7 -> 900 | BQ7: 0 | BR7: 0 | BS7: 0 | BT7: 0 | BU7: 0 | BV7: 0 | BW7: 0 | BX7: 0 | BY7: 0 | BZ7: 0 | CA7: 0 | CB7: 0 | CC7: 0 | CD7: 0 | CE7: 0 | CF7: 0 | CG7: 0 | CH7: 0 | CI7: 0 | CJ7: 0 | CK7: 0 | CL7: 0 | CM7: 0 | CN7: 0 | CO7: 0 | CP7: 0 | CQ7: 0 | CR7: 0 | CS7: 0 | CT7: 0 | CU7: 0 | CV7: 0 | CW7: 0 | CX7: 0 | CY7: 0 | CZ7: 0 | DA7: 0 | DB7: 0 | DC7: 0 | DD7: 0 | DE7: 0 | DF7: 0 | DG7: 0 | DH7: 0 | DI7: 0 | DJ7: 0 | DK7: 0 | DL7: 0 | DM7: 0 | DN7: 0 | DO7: 0 | DP7: 0 | DQ7: 0 | DR7: 0 | DS7: 0 | DT7: 0 | DU7: 0 | DV7: 0 | DW7: 0 | DX7: 0 | DY7: 0 | DZ7: 0 | EA7: 0 | EB7: 0 | EC7: 0 | ED7: 0 | EE7: 0 | EF7: 0 | EG7: 0 | EH7: 0 | EI7: 0 | EJ7: 0 | EK7: 0 | EL7: 0
A8: =Данные!A8 -> 4276 | B8: =Данные!B8 -> 2016 | C8: =Данные!C8 -> компьютерных технологий и электронного обучения | D8: =Данные!D8 -> Готская Ирина Борисовна | E8: =Данные!E8 -> доктор педагогических наук | F8: =Данные!F8 -> профессор | G8: =Данные!G8 -> 1 | H8: =Данные!H8 -> 14784 | ... L8: =Данные!L8 -> 120 | M8: =SUM(J8:L8)/10 -> 15.2 | N8: =2+(0.33*W8) -> 5.63 | O8: =0.25*W8 -> 2.75 | P8: =0.25*W8 -> 2.75 | Q8: =Данные!Q8 -> 0 | R8: =Данные!R8 -> 0 | S8: =Данные!S8 -> 0 | T8: =Данные!T8 -> 21 | U8: =Данные!U8 -> 0 | V8: =Данные!V8 -> 0 | W8: =Данные!W8 -> 11 | X8: =Данные!X8 -> 1 | ... AA8: =Данные!AA8 -> осн | AB8: =VLOOKUP(F8, $BN$3:$BO$15, 2, 0) -> 750 | AC8: =IF(IFERROR(MATCH(H8, $AK$4:$BL$4, 0), 0)>=1, "ИВТ (бак)", IF(IFERROR(MATCH(H8, $AK$5:$BL$5, 0), 0)>=1, "КЭО (маг)", "")) | AD8: =IF(IFERROR(MATCH(H8, $AK$4:$AN$4, 0), 0)=1, "2015–2016", IF(IFERROR(MATCH(H8, $AO$4:$AR$4, 0), 0)=1, "2016–2017", IF(IFERROR(MATCH(H8, $AS$4:$AV$4, 0), 0)=1, "2017–2018", IF(IFERROR(MATCH(H8, $AW$4:$AZ$4, 0), 0)=1, "2018–2019", IF(IFERROR(MATCH(H8, $BA$4:$BD$4, 0), 0)=1, "2019–2020", IF(IFERROR(MATCH(H8, $BE$4:$BH$4, 0), 0)=1, "2020–2021", IF(IFERROR(MATCH(H8, $BI$4:$BL$4, 0), 0)=1, "2021–2022", ""))))))) | AE8: =SUM(J8:V8) -> 199.33 | AF8: =AE8/AB8 -> 0.26577333 | AJ8: учебный год | AK8: 2015/2016 | AO8: 2016/2017 | AS8: 2017/2018 | AW8: 2018/2019 | BA8: 2019/2020 | BE8: 2020/2021 | BI8: 2021/2022 | BN8: =Данные!BG8 -> эксперт-программист | BO8: =Данные!BH8 -> 900 | BQ8: 0 | BR8: 0 | BS8: 0 | BT8: 0 | BU8: 0 | BV8: 0 | BW8: 0 | BX8: 0 | BY8: 0 | BZ8: 0 | CA8: 0 | CB8: 0 | CC8: 0 | CD8: 0 | CE8: 0 | CF8: 0 | CG8: 0 | CH8: 0 | CI8: 0 | CJ8: 0 | CK8: 0 | CL8: 0 | CM8: 0 | CN8: 0 | CO8: 0 | CP8: 0 | CQ8: 0 | CR8: 0 | CS8: 0 | CT8: 0 | CU8: 0 | CV8: 0 | CW8: 0 | CX8: 0 | CY8: 0 | CZ8: 0 | DA8: 0 | DB8: 0 | DC8: 0 | DD8: 0 | DE8: 0 | DF8: 0 | DG8: 0 | DH8: 0 | DI8: 0 | DJ8: 0 | DK8: 0 | DL8: 0 | DM8: 0 | DN8: 0 | DO8: 0 | DP8: 0 | DQ8: 0 | DR8: 0 | DS8: 0 | DT8: 0 | DU8: 0 | DV8: 0 | DW8: 0 | DX8: 0 | DY8: 0 | DZ8: 0 | EA8: 0 | EB8: 0 | EC8: 0 | ED8: 0 | EE8: 0 | EF8: 0 | EG8: 0 | EH8: 0 | EI8: 0 | EJ8: 0 | EK8: 0 | EL8: 0
A9: =Данные!A9 -> 4276 | B9: =Данные!B9 -> 2017 | C9: =Данные!C9 -> компьютерных технологий и электронного обучения | D9: =Данные!D9 -> Готская Ирина Борисовна | E9: =Данные!E9 -> доктор педагогических наук | F9: =Данные!F9 -> профессор | G9: =Данные!G9 -> 1 | H9: =Данные!H9 -> 16006 | ... L9: =Данные!L9 -> 60 | M9: =SUM(J9:L9)/10 -> 7.6 | N9: =2+(0.33*W9) -> 6.29 | O9: =0.25*W9 -> 3.25 | P9: =0.25*W9 -> 3.25 | Q9: =Данные!Q9 -> 0 | R9: =Данные!R9 -> 0 | S9: =Данные!S9 -> 0 | T9: =Данные!T9 -> 11 | U9: =Данные!U9 -> 0 | V9: =Данные!V9 -> 0 | W9: =Данные!W9 -> 13 | X9: =Данные!X9 -> 1 | ... AA9: =Данные!AA9 -> осн | AB9: =VLOOKUP(F9, $BN$3:$BO$15, 2, 0) -> 750 | AC9: =IF(IFERROR(MATCH(H9, $AK$4:$BL$4, 0), 0)>=1, "ИВТ (бак)", IF(IFERROR(MATCH(H9, $AK$5:$BL$5, 0), 0)>=1, "КЭО (маг)", "")) | AD9: =IF(IFERROR(MATCH(H9, $AK$4:$AN$4, 0), 0)=1, "2015–2016", IF(IFERROR(MATCH(H9, $AO$4:$AR$4, 0), 0)=1, "2016–2017", IF(IFERROR(MATCH(H9, $AS$4:$AV$4, 0), 0)=1, "2017–2018", IF(IFERROR(MATCH(H9, $AW$4:$AZ$4, 0), 0)=1, "2018–2019", IF(IFERROR(MATCH(H9, $BA$4:$BD$4, 0), 0)=1, "2019–2020", IF(IFERROR(MATCH(H9, $BE$4:$BH$4, 0), 0)=1, "2020–2021", IF(IFERROR(MATCH(H9, $BI$4:$BL$4, 0), 0)=1, "2021–2022", ""))))))) | AE9: =SUM(J9:V9) -> 107.39 | AF9: =AE9/AB9 -> 0.14318667 | AJ9: курс | AK9: 1 | AL9: 2 | AM9: 3 | AN9: 4 | AO9: 1 | AP9: 2 | AQ9: 3 | AR9: 4 | AS9: 1 | AT9: 2 | AU9: 3 | AV9: 4 | AW9: 1 | AX9: 2 | AY9: 3 | AZ9: 4 | BA9: 1 | BB9: 2 | BC9: 3 | BD9: 4 | BE9: 1 | BF9: 2 | BG9: 3 | BH9: 4 | BI9: 1 | BJ9: 2 | BK9: 3 | BL9: 4 | BN9: =Данные!BG9 -> и.о.доцент | BO9: =Данные!BH9 -> 900 | BQ9: 0 | BR9: 0 | BS9: 0 | BT9: 0 | BU9: 0 | BV9: 0 | BW9: 0 | BX9: 0 | BY9: 0 | BZ9: 0 | CA9: 0 | CB9: 0 | CC9: 0 | CD9: 0 | CE9: 0 | CF9: 0 | CG9: 0 | CH9: 0 | CI9: 0 | CJ9: 0 | CK9: 0 | CL9: 0 | CM9: 0 | CN9: 0 | CO9: 0 | CP9: 0 | CQ9: 0 | CR9: 0 | CS9: 0 | CT9: 0 | CU9: 0 | CV9: 0 | CW9: 0 | CX9: 0 | CY9: 0 | CZ9: 0 | DA9: 0 | DB9: 0 | DC9: 0 | DD9: 0 | DE9: 0 | DF9: 0 | DG9: 0 | DH9: 0 | DI9: 0 | DJ9: 0 | DK9: 0 | DL9: 0 | DM9: 0 | DN9: 0 | DO9: 0 | DP9: 0 | DQ9: 0 | DR9: 0 | DS9: 0 | DT9: 0 | DU9: 0 | DV9: 0 | DW9: 0 | DX9: 0 | DY9: 0 | DZ9: 0 | EA9: 0 | EB9: 0 | EC9: 0 | ED9: 0 | EE9: 0 | EF9: 0 | EG9: 0 | EH9: 0 | EI9: 0 | EJ9: 0 | EK9: 0 | EL9: 0
A10: =Данные!A10 -> 4277 | B10: =Данные!B10 -> 2017 | C10: =Данные!C10 -> компьютерных технологий и электронного обучения | D10: =Данные!D10 -> Абрамян Геннадий Владимирович | E10: =Данные!E10 -> доктор педагогических наук | F10: =Данные!F10 -> профессор | G10: =Данные!G10 -> 1 | H10: =Данные!H10 -> 16005 | ... L10: =Данные!L10 -> 54 | M10: =SUM(J10:L10)/10 -> 7.2 | N10: =2+(0.33*W10) -> 5.96 | O10: =0.25*W10 -> 3 | P10: =0.25*W10 -> 3 | Q10: =Данные!Q10 -> 0 | R10: =Данные!R10 -> 0 | S10: =Данные!S10 -> 0 | T10: =Данные!T10 -> 11 | U10: =Данные!U10 -> 0 | V10: =Данные!V10 -> 0 | W10: =Данные!W10 -> 12 | X10: =Данные!X10 -> 1 | ... AA10: =Данные!AA10 -> осн | AB10: =VLOOKUP(F10, $BN$3:$BO$15, 2, 0) -> 750 | AC10: =IF(IFERROR(MATCH(H10, $AK$4:$BL$4, 0), 0)>=1, "ИВТ (бак)", IF(IFERROR(MATCH(H10, $AK$5:$BL$5, 0), 0)>=1, "КЭО (маг)", "")) | AD10: =IF(IFERROR(MATCH(H10, $AK$4:$AN$4, 0), 0)=1, "2015–2016", IF(IFERROR(MATCH(H10, $AO$4:$AR$4, 0), 0)=1, "2016–2017", IF(IFERROR(MATCH(H10, $AS$4:$AV$4, 0), 0)=1, "2017–2018", IF(IFERROR(MATCH(H10, $AW$4:$AZ$4, 0), 0)=1, "2018–2019", IF(IFERROR(MATCH(H10, $BA$4:$BD$4, 0), 0)=1, "2019–2020", IF(IFERROR(MATCH(H10, $BE$4:$BH$4, 0), 0)=1, "2020–2021", IF(IFERROR(MATCH(H10, $BI$4:$BL$4, 0), 0)=1, "2021–2022", ""))))))) | AE10: =SUM(J10:V10) -> 102.16 | AF10: =AE10/AB10 -> 0.13621333 | AJ10: год поступления | AK10: 2015 | AL10: 2014 | AM10: 2013 | AN10: 2012 | AO10: 2016 | AP10: 2015 | AQ10: 2014 | AR10: 2013 | AS10: 2017 | AT10: 2016 | AU10: 2015 | AV10: 2014 | AW10: 2018 | AX10: 2017 | AY10: 2016 | AZ10: 2015 | BA10: 2019 | BB10: 2018 | BC10: 2017 | BD10: 2016 | BE10: 2020 | BF10: 2019 | BG10: 2018 | BH10: 2017 | BI10: 2021 | BJ10: 2020 | BK10: 2019 | BL10: 2018 | BN10: =Данные!BG10 -> внешний | BO10: =Данные!BH10 -> 900 | BQ10: 0 | BR10: 0 | BS10: 0 | BT10: 0 | BU10: 0 | BV10: 0 | BW10: 0 | BX10: 0 | BY10: 0 | BZ10: 0 | CA10: 0 | CB10: 0 | CC10: 0 | CD10: 0 | CE10: 0 | CF10: 0 | CG10: 0 | CH10: 0 | CI10: 0 | CJ10: 0 | CK10: 0 | CL10: 0 | CM10: 0 | CN10: 0 | CO10: 0 | CP10: 0 | CQ10: 0 | CR10: 0 | CS10: 0 | CT10: 0 | CU10: 0 | CV10: 0 | CW10: 0 | CX10: 0 | CY10: 0 | CZ10: 0 | DA10: 0 | DB10: 0 | DC10: 0 | DD10: 0 | DE10: 0 | DF10: 0 | DG10: 0 | DH10: 0 | DI10: 0 | DJ10: 0 | DK10: 0 | DL10: 0 | DM10: 0 | DN10: 0 | DO10: 0 | DP10: 0 | DQ10: 0 | DR10: 0 | DS10: 0 | DT10: 0 | DU10: 0 | DV10: 0 | DW10: 0 | DX10: 0 | DY10: 0 | DZ10: 0 | EA10: 0 | EB10: 0 | EC10: 0 | ED10: 0 | EE10: 0 | EF10: 0 | EG10: 0 | EH10: 0 | EI10: 0 | EJ10: 0 | EK10: 0 | EL10: 0
A11: =Данные!A11 -> 4277 | B11: =Данные!B11 -> 2018 | C11: =Данные!C11 -> компьютерных технологий и электронного обучения | D11: =Данные!D11 -> Абрамян Геннадий Владимирович | E11: =Данные!E11 -> доктор педагогических наук | F11: =Данные!F11 -> профессор | G11: =Данные!G11 -> 1 | H11: =Данные!H11 -> 17336 | ... L11: =Данные!L11 -> 36 | M11: =SUM(J11:L11)/10 -> 3.6 | N11: =2+(0.33*W11) -> 9.59 | O11: =0.25*W11 -> 5.75 | P11: =0.25*W11 -> 5.75 | Q11: =Данные!Q11 -> 0 | R11: =Данные!R11 -> 0 | S11: =Данные!S11 -> 0 | T11: =Данные!T11 -> 11 | U11: =Данные!U11 -> 0 | V11: =Данные!V11 -> 0 | W11: =Данные!W11 -> 23 | X11: =Данные!X11 -> 1 | ... AA11: =Данные!AA11 -> осн | AB11: =VLOOKUP(F11, $BN$3:$BO$15, 2, 0) -> 750 | AC11: =IF(IFERROR(MATCH(H11, $AK$4:$BL$4, 0), 0)>=1, "ИВТ (бак)", IF(IFERROR(MATCH(H11, $AK$5:$BL$5, 0), 0)>=1, "КЭО (маг)", "")) | AD11: =IF(IFERROR(MATCH(H11, $AK$4:$AN$4, 0), 0)=1, "2015–2016", IF(IFERROR(MATCH(H11, $AO$4:$AR$4, 0), 0)=1, "2016–2017", IF(IFERROR(MATCH(H11, $AS$4:$AV$4, 0), 0)=1, "2017–2018", IF(IFERROR(MATCH(H11, $AW$4:$AZ$4, 0), 0)=1, "2018–2019", IF(IFERROR(MATCH(H11, $BA$4:$BD$4, 0), 0)=1, "2019–2020", IF(IFERROR(MATCH(H11, $BE$4:$BH$4, 0), 0)=1, "2020–2021", IF(IFERROR(MATCH(H11, $BI$4:$BL$4, 0), 0)=1, "2021–2022", ""))))))) | AE11: =SUM(J11:V11) -> 71.69 | AF11: =AE11/AB11 -> 0.095586667 | AJ11: Бакалавры (ИВТ) | AK11: =Данные!AD11 -> 13 | AL11: =Данные!AE11 -> 15 | AM11: =Данные!AF11 -> 24 | AN11: =Данные!AG11 -> 34 | AO11: =Данные!AH11 -> 27 | AP11: =Данные!AI11 -> 13 | AQ11: =Данные!AJ11 -> 56 | AR11: =Данные!AK11 -> 55 | ... BL11: =Данные!BE11 -> 39 | BN11: =Данные!BG11 -> должность | BO11: =Данные!BH11 -> 1 | BQ11: 0 | BR11: 0 | BS11: 0 | BT11: 0 | BU11: 0 | BV11: 0 | BW11: 0 | BX11: 0 | BY11: 0 | BZ11: 0 | CA11: 0 | CB11: 0 | CC11: 0 | CD11: 0 | CE11: 0 | CF11: 0 | CG11: 0 | CH11: 0 | CI11: 0 | CJ11: 0 | CK11: 0 | CL11: 0 | CM11: 0 | CN11: 0 | CO11: 0 | CP11: 0 | CQ11: 0 | CR11: 0 | CS11: 0 | CT11: 0 | CU11: 0 | CV11: 0 | CW11: 0 | CX11: 0 | CY11: 0 | CZ11: 0 | DA11: 0 | DB11: 0 | DC11: 0 | DD11: 0 | DE11: 0 | DF11: 0 | DG11: 0 | DH11: 0 | DI11: 0 | DJ11: 0 | DK11: 0 | DL11: 0 | DM11: 0 | DN11: 0 | DO11: 0 | DP11: 0 | DQ11: 0 | DR11: 0 | DS11: 0 | DT11: 0 | DU11: 0 | DV11: 0 | DW11: 0 | DX11: 0 | DY11: 0 | DZ11: 0 | EA11: 0 | EB11: 0 | EC11: 0 | ED11: 0 | EE11: 0 | EF11: 0 | EG11: 0 | EH11: 0 | EI11: 0 | EJ11: 0 | EK11: 0 | EL11: 0
A12: =Данные!A12 -> 4699 | B12: =Данные!B12 -> 2016 | C12: =Данные!C12 -> компьютерных технологий и электронного обучения | D12: =Данные!D12 -> Полякова Наталия Александровна | E12: =Данные!E12 -> кандидат педагогических наук | F12: =Данные!F12 -> доцент | G12: =Данные!G12 -> 1 | H12: =Данные!H12 -> 15014 | ... L12: =Данные!L12 -> 0 | M12: =SUM(J12:L12)/10 -> 4.1 | N12: =2+(0.33*W12) -> 8.93 | O12: =0.25*W12 -> 5.25 | P12: =0.25*W12 -> 5.25 | Q12: =Данные!Q12 -> 0 | R12: =Данные!R12 -> 0 | S12: =Данные!S12 -> 0 | T12: =Данные!T12 -> 6 | U12: =Данные!U12 -> 0 | V12: =Данные!V12 -> 0 | W12: =Данные!W12 -> 21 | X12: =Данные!X12 -> 1 | ... AA12: =Данные!AA12 -> осн | AB12: =VLOOKUP(F12, $BN$3:$BO$15, 2, 0) -> 800 | AC12: =IF(IFERROR(MATCH(H12, $AK$4:$BL$4, 0), 0)>=1, "ИВТ (бак)", IF(IFERROR(MATCH(H12, $AK$5:$BL$5, 0), 0)>=1, "КЭО (маг)", "")) | AD12: =IF(IFERROR(MATCH(H12, $AK$4:$AN$4, 0), 0)=1, "2015–2016", IF(IFERROR(MATCH(H12, $AO$4:$AR$4, 0), 0)=1, "2016–2017", IF(IFERROR(MATCH(H12, $AS$4:$AV$4, 0), 0)=1, "2017–2018", IF(IFERROR(MATCH(H12, $AW$4:$AZ$4, 0), 0)=1, "2018–2019", IF(IFERROR(MATCH(H12, $BA$4:$BD$4, 0), 0)=1, "2019–2020", IF(IFERROR(MATCH(H12, $BE$4:$BH$4, 0), 0)=1, "2020–2021", IF(IFERROR(MATCH(H12, $BI$4:$BL$4, 0), 0)=1, "2021–2022", ""))))))) | AE12: =SUM(J12:V12) -> 70.53 | AF12: =AE12/AB12 -> 0.0881625 | AJ12: Магистры (КЭО) | AK12: =Данные!AD12 -> 10 | AL12: =Данные!AE12 -> 23 | AO12: =Данные!AH12 -> 56 | AP12: =Данные!AI12 -> 34 | AS12: =Данные!AL12 -> 10 | AT12: =Данные!AM12 -> 10 | AW12: =Данные!AP12 -> 10 | AX12: =Данные!AQ12 -> 10 | BA12: =Данные!AT12 -> 27 | BB12: =Данные!AU12 -> 10 | BE12: =Данные!AX12 -> 43 | BF12: =Данные!AY12 -> 38 | BI12: =Данные!BB12 -> 43 | BJ12: =Данные!BC12 -> 45 | BN12: =Данные!BG12 -> должность | BO12: =Данные!BH12 -> 1 | BQ12: 0 | BR12: 0 | BS12: 0 | BT12: 0 | BU12: 0 | BV12: 0 | BW12: 0 | BX12: 0 | BY12: 0 | BZ12: 0 | CA12: 0 | CB12: 0 | CC12: 0 | CD12: 0 | CE12: 0 | CF12: 0 | CG12: 0 | CH12: 0 | CI12: 0 | CJ12: 0 | CK12: 0 | CL12: 0 | CM12: 0 | CN12: 0 | CO12: 0 | CP12: 0 | CQ12: 0 | CR12: 0 | CS12: 0 | CT12: 0 | CU12: 0 | CV12: 0 | CW12: 0 | CX12: 0 | CY12: 0 | CZ12: 0 | DA12: 0 | DB12: 0 | DC12: 0 | DD12: 0 | DE12: 0 | DF12: 0 | DG12: 0 | DH12: 0 | DI12: 0 | DJ12: 0 | DK12: 0 | DL12: 0 | DM12: 0 | DN12: 0 | DO12: 0 | DP12: 0 | DQ12: 0 | DR12: 0 | DS12: 0 | DT12: 0 | DU12: 0 | DV12: 0 | DW12: 0 | DX12: 0 | DY12: 0 | DZ12: 0 | EA12: 0 | EB12: 0 | EC12: 0 | ED12: 0 | EE12: 0 | EF12: 0 | EG12: 0 | EH12: 0 | EI12: 0 | EJ12: 0 | EK12: 0 | EL12: 0
A13: =Данные!A13 -> 4699 | B13: =Данные!B13 -> 2018 | C13: =Данные!C13 -> компьютерных технологий и электронного обучения | D13: =Данные!D13 -> Абрамян Геннадий Владимирович | E13: =Данные!E13 -> доктор педагогических наук | F13: =Данные!F13 -> профессор | G13: =Данные!G13 -> 1 | H13: =Данные!H13 -> 17337 | ... L13: =Данные!L13 -> 54 | M13: =SUM(J13:L13)/10 -> 7.2 | N13: =2+(0.33*W13) -> 9.92 | O13: =0.25*W13 -> 6 | P13: =0.25*W13 -> 6 | Q13: =Данные!Q13 -> 0 | R13: =Данные!R13 -> 0 | S13: =Данные!S13 -> 0 | T13: =Данные!T13 -> 10 | U13: =Данные!U13 -> 0 | V13: =Данные!V13 -> 0 | W13: =Данные!W13 -> 24 | X13: =Данные!X13 -> 1 | ... AA13: =Данные!AA13 -> осн | AB13: =VLOOKUP(F13, $BN$3:$BO$15, 2, 0) -> 750 | AC13: =IF(IFERROR(MATCH(H13, $AK$4:$BL$4, 0), 0)>=1, "ИВТ (бак)", IF(IFERROR(MATCH(H13, $AK$5:$BL$5, 0), 0)>=1, "КЭО (маг)", "")) | AD13: =IF(IFERROR(MATCH(H13, $AK$4:$AN$4, 0), 0)=1, "2015–2016", IF(IFERROR(MATCH(H13, $AO$4:$AR$4, 0), 0)=1, "2016–2017", IF(IFERROR(MATCH(H13, $AS$4:$AV$4, 0), 0)=1, "2017–2018", IF(IFERROR(MATCH(H13, $AW$4:$AZ$4, 0), 0)=1, "2018–2019", IF(IFERROR(MATCH(H13, $BA$4:$BD$4, 0), 0)=1, "2019–2020", IF(IFERROR(MATCH(H13, $BE$4:$BH$4, 0), 0)=1, "2020–2021", IF(IFERROR(MATCH(H13, $BI$4:$BL$4, 0), 0)=1, "2021–2022", ""))))))) | AE13: =SUM(J13:V13) -> 111.12 | AF13: =AE13/AB13 -> 0.14816 | BN13: =Данные!BG13 -> должность | BO13: =Данные!BH13 -> 1 | BQ13: 0 | BR13: 0 | BS13: 0 | BT13: 0 | BU13: 0 | BV13: 0 | BW13: 0 | BX13: 0 | BY13: 0 | BZ13: 0 | CA13: 0 | CB13: 0 | CC13: 0 | CD13: 0 | CE13: 0 | CF13: 0 | CG13: 0 | CH13: 0 | CI13: 0 | CJ13: 0 | CK13: 0 | CL13: 0 | CM13: 0 | CN13: 0 | CO13: 0 | CP13: 0 | CQ13: 0 | CR13: 0 | CS13: 0 | CT13: 0 | CU13: 0 | CV13: 0 | CW13: 0 | CX13: 0 | CY13: 0 | CZ13: 0 | DA13: 0 | DB13: 0 | DC13: 0 | DD13: 0 | DE13: 0 | DF13: 0 | DG13: 0 | DH13: 0 | DI13: 0 | DJ13: 0 | DK13: 0 | DL13: 0 | DM13: 0 | DN13: 0 | DO13: 0 | DP13: 0 | DQ13: 0 | DR13: 0 | DS13: 0 | DT13: 0 | DU13: 0 | DV13: 0 | DW13: 0 | DX13: 0 | DY13: 0 | DZ13: 0 | EA13: 0 | EB13: 0 | EC13: 0 | ED13: 0 | EE13: 0 | EF13: 0 | EG13: 0 | EH13: 0 | EI13: 0 | EJ13: 0 | EK13: 0 | EL13: 0
A14: =Данные!A14 -> 4701 | B14: =Данные!B14 -> 2016 | C14: =Данные!C14 -> компьютерных технологий и электронного обучения | D14: =Данные!D14 -> Аксютин Павел Александрович | E14: =Данные!E14 -> нет | F14: =Данные!F14 -> ассистент | G14: =Данные!G14 -> 0.5 | H14: =Данные!H14 -> 15313 | ... L14: =Данные!L14 -> 0 | M14: =SUM(J14:L14)/10 -> 0 | N14: =2+(0.33*W14) -> 8.6 | O14: =0.25*W14 -> 5 | P14: =0.25*W14 -> 5 | Q14: =Данные!Q14 -> 0 | R14: =Данные!R14 -> 0 | S14: =Данные!S14 -> 0 | T14: =Данные!T14 -> 7 | U14: =Данные!U14 -> 0 | V14: =Данные!V14 -> 0 | W14: =Данные!W14 -> 20 | X14: =Данные!X14 -> 1 | ... AA14: =Данные!AA14 -> осн | AB14: =VLOOKUP(F14, $BN$3:$BO$15, 2, 0) -> 900 | AC14: =IF(IFERROR(MATCH(H14, $AK$4:$BL$4, 0), 0)>=1, "ИВТ (бак)", IF(IFERROR(MATCH(H14, $AK$5:$BL$5, 0), 0)>=1, "КЭО (маг)", "")) | AD14: =IF(IFERROR(MATCH(H14, $AK$4:$AN$4, 0), 0)=1, "2015–2016", IF(IFERROR(MATCH(H14, $AO$4:$AR$4, 0), 0)=1, "2016–2017", IF(IFERROR(MATCH(H14, $AS$4:$AV$4, 0), 0)=1, "2017–2018", IF(IFERROR(MATCH(H14, $AW$4:$AZ$4, 0), 0)=1, "2018–2019", IF(IFERROR(MATCH(H14, $BA$4:$BD$4, 0), 0)=1, "2019–2020", IF(IFERROR(MATCH(H14, $BE$4:$BH$4, 0), 0)=1, "2020–2021", IF(IFERROR(MATCH(H14, $BI$4:$BL$4, 0), 0)=1, "2021–2022", ""))))))) | AE14: =SUM(J14:V14) -> 25.6 | AF14: =AE14/AB14 -> 0.028444444 | BN14: =Данные!BG14 -> должность | BO14: =Данные!BH14 -> 1 | BQ14: 0 | BR14: 0 | BS14: 0 | BT14: 0 | BU14: 0 | BV14: 0 | BW14: 0 | BX14: 0 | BY14: 0 | BZ14: 0 | CA14: 0 | CB14: 0 | CC14: 0 | CD14: 0 | CE14: 0 | CF14: 0 | CG14: 0 | CH14: 0 | CI14: 0 | CJ14: 0 | CK14: 0 | CL14: 0 | CM14: 0 | CN14: 0 | CO14: 0 | CP14: 0 | CQ14: 0 | CR14: 0 | CS14: 0 | CT14: 0 | CU14: 0 | CV14: 0 | CW14: 0 | CX14: 0 | CY14: 0 | CZ14: 0 | DA14: 0 | DB14: 0 | DC14: 0 | DD14: 0 | DE14: 0 | DF14: 0 | DG14: 0 | DH14: 0 | DI14: 0 | DJ14: 0 | DK14: 0 | DL14: 0 | DM14: 0 | DN14: 0 | DO14: 0 | DP14: 0 | DQ14: 0 | DR14: 0 | DS14: 0 | DT14: 0 | DU14: 0 | DV14: 0 | DW14: 0 | DX14: 0 | DY14: 0 | DZ14: 0 | EA14: 0 | EB14: 0 | EC14: 0 | ED14: 0 | EE14: 0 | EF14: 0 | EG14: 0 | EH14: 0 | EI14: 0 | EJ14: 0 | EK14: 0 | EL14: 0
A15: =Данные!A15 -> 4701 | B15: =Данные!B15 -> 2016 | C15: =Данные!C15 -> компьютерных технологий и электронного обучения | D15: =Данные!D15 -> Власова Елена Зотиковна | E15: =Данные!E15 -> доктор педагогических наук | F15: =Данные!F15 -> заведующий кафедрой | G15: =Данные!G15 -> 1 | H15: =Данные!H15 -> 15313 | ... L15: =Данные!L15 -> 0 | M15: =SUM(J15:L15)/10 -> 0.2 | N15: =2+(0.33*W15) -> 8.6 | O15: =0.25*W15 -> 5 | P15: =0.25*W15 -> 5 | Q15: =Данные!Q15 -> 0 | R15: =Данные!R15 -> 0 | S15: =Данные!S15 -> 0 | T15: =Данные!T15 -> 9 | U15: =Данные!U15 -> 0 | V15: =Данные!V15 -> 0 | W15: =Данные!W15 -> 20 | X15: =Данные!X15 -> 1 | ... AA15: =Данные!AA15 -> осн | AB15: =VLOOKUP(F15, $BN$3:$BO$15, 2, 0) -> 700 | AC15: =IF(IFERROR(MATCH(H15, $AK$4:$BL$4, 0), 0)>=1, "ИВТ (бак)", IF(IFERROR(MATCH(H15, $AK$5:$BL$5, 0), 0)>=1, "КЭО (маг)", "")) | AD15: =IF(IFERROR(MATCH(H15, $AK$4:$AN$4, 0), 0)=1, "2015–2016", IF(IFERROR(MATCH(H15, $AO$4:$AR$4, 0), 0)=1, "2016–2017", IF(IFERROR(MATCH(H15, $AS$4:$AV$4, 0), 0)=1, "2017–2018", IF(IFERROR(MATCH(H15, $AW$4:$AZ$4, 0), 0)=1, "2018–2019", IF(IFERROR(MATCH(H15, $BA$4:$BD$4, 0), 0)=1, "2019–2020", IF(IFERROR(MATCH(H15, $BE$4:$BH$4, 0), 0)=1, "2020–2021", IF(IFERROR(MATCH(H15, $BI$4:$BL$4, 0), 0)=1, "2021–2022", ""))))))) | AE15: =SUM(J15:V15) -> 29.8 | AF15: =AE15/AB15 -> 0.042571429 | BN15: =Данные!BG15 -> должность | BO15: =Данные!BH15 -> 1 | BQ15: 0 | BR15: 0 | BS15: 0 | BT15: 0 | BU15: 0 | BV15: 0 | BW15: 0 | BX15: 0 | BY15: 0 | BZ15: 0 | CA15: 0 | CB15: 0 | CC15: 0 | CD15: 0 | CE15: 0 | CF15: 0 | CG15: 0 | CH15: 0 | CI15: 0 | CJ15: 0 | CK15: 0 | CL15: 0 | CM15: 0 | CN15: 0 | CO15: 0 | CP15: 0 | CQ15: 0 | CR15: 0 | CS15: 0 | CT15: 0 | CU15: 0 | CV15: 0 | CW15: 0 | CX15: 0 | CY15: 0 | CZ15: 0 | DA15: 0 | DB15: 0 | DC15: 0 | DD15: 0 | DE15: 0 | DF15: 0 | DG15: 0 | DH15: 0 | DI15: 0 | DJ15: 0 | DK15: 0 | DL15: 0 | DM15: 0 | DN15: 0 | DO15: 0 | DP15: 0 | DQ15: 0 | DR15: 0 | DS15: 0 | DT15: 0 | DU15: 0 | DV15: 0 | DW15: 0 | DX15: 0 | DY15: 0 | DZ15: 0 | EA15: 0 | EB15: 0 | EC15: 0 | ED15: 0 | EE15: 0 | EF15: 0 | EG15: 0 | EH15: 0 | EI15: 0 | EJ15: 0 | EK15: 0 | EL15: 0
A16: =Данные!A16 -> 4701 | B16: =Данные!B16 -> 2016 | C16: =Данные!C16 -> компьютерных технологий и электронного обучения | D16: =Данные!D16 -> Гончарова Светлана Викторовна | E16: =Данные!E16 -> кандидат педагогических наук | F16: =Данные!F16 -> доцент | G16: =Данные!G16 -> 1 | H16: =Данные!H16 -> 15313 | ... L16: =Данные!L16 -> 51 | M16: =SUM(J16:L16)/10 -> 8.3 | N16: =2+(0.33*W16) -> 8.6 | O16: =0.25*W16 -> 5 | P16: =0.25*W16 -> 5 | Q16: =Данные!Q16 -> 0 | R16: =Данные!R16 -> 0 | S16: =Данные!S16 -> 0 | T16: =Данные!T16 -> 4 | U16: =Данные!U16 -> 0 | V16: =Данные!V16 -> 0 | W16: =Данные!W16 -> 20 | X16: =Данные!X16 -> 1 | ... AA16: =Данные!AA16 -> осн | AB16: =VLOOKUP(F16, $BN$3:$BO$15, 2, 0) -> 800 | AC16: =IF(IFERROR(MATCH(H16, $AK$4:$BL$4, 0), 0)>=1, "ИВТ (бак)", IF(IFERROR(MATCH(H16, $AK$5:$BL$5, 0), 0)>=1, "КЭО (маг)", "")) | AD16: =IF(IFERROR(MATCH(H16, $AK$4:$AN$4, 0), 0)=1, "2015–2016", IF(IFERROR(MATCH(H16, $AO$4:$AR$4, 0), 0)=1, "2016–2017", IF(IFERROR(MATCH(H16, $AS$4:$AV$4, 0), 0)=1, "2017–2018", IF(IFERROR(MATCH(H16, $AW$4:$AZ$4, 0), 0)=1, "2018–2019", IF(IFERROR(MATCH(H16, $BA$4:$BD$4, 0), 0)=1, "2019–2020", IF(IFERROR(MATCH(H16, $BE$4:$BH$4, 0), 0)=1, "2020–2021", IF(IFERROR(MATCH(H16, $BI$4:$BL$4, 0), 0)=1, "2021–2022", ""))))))) | AE16: =SUM(J16:V16) -> 113.9 | AF16: =AE16/AB16 -> 0.142375 | BQ16: 0 | BR16: 0 | BS16: 0 | BT16: 0 | BU16: 0 | BV16: 0 | BW16: 0 | BX16: 0 | BY16: 0 | BZ16: 0 | CA16: 0 | CB16: 0 | CC16: 0 | CD16: 0 | CE16: 0 | CF16: 0 | CG16: 0 | CH16: 0 | CI16: 0 | CJ16: 0 | CK16: 0 | CL16: 0 | CM16: 0 | CN16: 0 | CO16: 0 | CP16: 0 | CQ16: 0 | CR16: 0 | CS16: 0 | CT16: 0 | CU16: 0 | CV16: 0 | CW16: 0 | CX16: 0 | CY16: 0 | CZ16: 0 | DA16: 0 | DB16: 0 | DC16: 0 | DD16: 0 | DE16: 0 | DF16: 0 | DG16: 0 | DH16: 0 | DI16: 0 | DJ16: 0 | DK16: 0 | DL16: 0 | DM16: 0 | DN16: 0 | DO16: 0 | DP16: 0 | DQ16: 0 | DR16: 0 | DS16: 0 | DT16: 0 | DU16: 0 | DV16: 0 | DW16: 0 | DX16: 0 | DY16: 0 | DZ16: 0 | EA16: 0 | EB16: 0 | EC16: 0 | ED16: 0 | EE16: 0 | EF16: 0 | EG16: 0 | EH16: 0 | EI16: 0 | EJ16: 0 | EK16: 0 | EL16: 0
